Workbook

Sheet 🏠 Master Dashboard
A1: 🧬 A7DO DNA MASTER v5 — FINAL Unified Organism Runtime
A2: All phases: Biology · Cognition · Phase 3 Experiential · Phase 4 Cognitive · Learning Loop · Phase 7 Wisdom
A3: Source: DNA_Consolidated_v17 (newest) + Master_v3 Phase 4 + Consolidated_v9 Phase 3 + Phase 7 NEW + Learning Loop NEW
A5: ⚡ MASTER TICK CONTROL
A6: Parameter | B6: Value | C6: Unit | D6: Notes
A7: Current Tick: | B7: 10,000 (default) | C7: ticks | D7: Edit in 🧬 DNA Loop Engine B4
A8: Current Week: | B8: 125 | C8: weeks | D8: Tick ÷ 80
A9: Life Stage: | B9: Toddler | D9: VLOOKUP from life stage map
A10: Birth Occurred: | B10: ✅ YES | D10: Tick ≥ 3,200
A11: Height: | B11: ~90 cm | C11: cm | D11: Growth formula active
A12: Mass: | B12: ~13 kg | C12: kg | D12: Growth formula active
A13: Heart Rate: | B13: ~110 bpm | C13: bpm | D13: Declining from 140 at birth
A14: Vocabulary: | B14: ~8,754 words | C14: words | D14: Logistic V(t) formula
A15: Motor Stage: | B15: 3 / 5 | C15: 1–5 | D15: Threshold-based
A16: ToM Stage: | B16: 1 — Proto-ToM | C16: 1–5 | D16: Wk 125 = Stage 1
A17: Consciousness C: | B17: 0.398 | C17: 0–1 | D17: EQ_CONS_10 verified
A18: Attachment Drive: | B18: 0.950 | C18: 0–1 | D18: Strong caregiver bond
A19: LTM Events: | B19: 9,590 | C19: events | D19: Episodic memory store
A20: Learning Loop: | B20: ✅ Active — Stage: Exposure/Interaction/Repetition | D20: Sleep every 800 ticks
A21: Phase 7 Active: | B21: ⏳ Pending — activates Tick 96,000 (Wk 1,200) | D21: W(t) rises 0→1 by Wk 2,000
A24: 🔄 LEARNING LOOP — 4-Stage Cycle
A25: Stage | B25: Name | C25: Fires Every | D25: Key Engines | E25: Output
A26: 1 | B26: Exposure | C26: Every tick | D26: EQ_SENS_06 · EQ_EMOT_07 · EQ_ATTN_09 | E26: Sensory vector · attention weight · emotional delta
A27: 2 | B27: Interaction | C27: Every 5 ticks | D27: EQ_PRED_08 · Motor Planning · Value TD(λ) | E27: Reinforcement · motor update · prediction error reduction
A28: 3 | B28: Repetition | C28: Every 10 ticks | D28: EQ_LANG_12 · G(word) · Scene Graph · ToM | E28: Word-object bindings · concept formation · NPC models
A29: 4 | B29: Sleep Consolidation | C29: Every 800 ticks | D29: Episodic Memory · EQ_PRED_08 dream replay | E29: Stable knowledge · grounded language · pruned LTM
A32: 🆕 PHASE 7 — CREATIVE SYNTHESIS & WISDOM ENGINE (Tick 96,000+)
A33: Equation | B33: Engine | C33: Fires Every | D33: Core Formula
A34: EQ_CREAT_17 | B34: ✨ Creative Synthesis Engine | C34: 500 ticks | D34: C_new(t) = α_c·(M_episodic ⊕ M_semantic) + β_c·(P_sim ⊗ S_skills) + γ_c·Noise
A35: EQ_WISDOM_18 | B35: 🦉 Wisdom Index Engine | C35: 500 ticks | D35: W(t+1) = W(t) + η_w·[λ1·C50yr + λ2·EthicalWeight + λ3·EmpathyIndex − λ4·ImpulseDrive]
A36: EQ_CAREER_19 | B36: 🎯 Career Specialisation Engine | C36: 1000 ticks | D36: Career(t+1) = Career(t) + η_car·[SkillVector · OpportunityMatrix · IdentityVector]
A37: EQ_LEGACY_20 | B37: 🌟 Legacy Projection Engine | C37: 2000 ticks | D37: L(t+1) = L(t) + η_l·[Impact_direct + Impact_indirect + CulturalTransmission − Entropy_f·L(t)]
A40: 🗂️ COMPLETE SHEET INDEX — 36 Sheets
A41: Sheet | B41: Category | C41: Cells | D41: Key Content
A42: 🧬 DNA Loop Engine | B42: Core | C42: 907 | D42: Tick control · lifecycle table · Phase 7 rows · life stage map
A43: 📈 Growth Timeline | B43: Core | C43: 3395 | D43: 292-row lifecycle · organ activation · milestones · maturity %
A44: 🧮 Mathematical Framework | B44: Core | C44: 1411 | D44: EQ_DNA_01→EQ_LANG_12 + EQ_CREAT_17→EQ_LEGACY_20 · all equations
A45: ⚙️ Parameters | B45: Core | C45: 297 | D45: 41 biological constants · Phase 7 params · tick frequency schedule
A46: 📖 System Specification | B46: Core | C46: 1004 | D46: Full system spec · architecture · module contracts
A47: 🧬 Prenatal & Genesis | B47: Biology | C47: 1469 | D47: Parental genesis · genetic inheritance · sex determination · hormones
...

Sheet 🧬 DNA Loop Engine
A1: 🧬 A7DO DNA LOOP ENGINE — LIVE CONTROL PANEL | Change B4 (Current Tick) to simulate any life stage
A2: ⚡ INPUT CELL → B4 (Current Tick) — Type any tick value (0–96000) to update ALL formulas below automatically
A3: ⚙️ CONTROL PANEL | D3: 🫀 ORGAN ACTIVATION STATUS | G3: 🔄 TICK ADVANCE LOGIC | J3: ⚡ GROWTH ENGINE
A4: Current Tick: | B4: 10000 | C4: ← EDIT THIS | D4: Organ/System | E4: Status | F4: DNA Code | G4: Parameter | H4: Value | J4: Parameter | K4: Value
A5: Current Week: | B5: =ROUND(B4/80,0) -> 125 | C5: weeks | D5: Neural Plate | E5: =IF(B5>=0,"✅ Active","⏳ Pending") -> ✅ Active | F5: NP_FORM | G5: Next Tick ID: | H5: =IF(B4<B6,"T"&TEXT(B4+100,"0000"),"COMPLETE") -> COMPLETE | J5: Growth Factor: | K5: =IF(B5>=40,1,IFERROR(VLOOKUP(B5,'🧬 DNA Loop Engine'!B29:G60,3,TRUE()),0.01)) -> 1
A6: Birth Tick: | B6: 3200 | C6: Fixed = 3200 | D6: Heart | E6: =IF(B5>=4,"✅ Active","⏳ Pending") -> ✅ Active | F6: HT_PART | G6: Ticks to Birth: | H6: =MAX(0,B6-B4) -> 0 | J6: Neural Gain: | K6: =IF(B5>=40,1,IFERROR(VLOOKUP(B5,'🧬 DNA Loop Engine'!B29:G60,4,TRUE()),0)) -> 1
A7: Nutrient Flow Rate: | B7: 1 | C7: Fixed = 1.0 | D7: Limbs | E7: =IF(B5>=8,"✅ Active","⏳ Pending") -> ✅ Active | F7: LM_DIFF | G7: Progress %: | H7: =TEXT(MIN(1,B4/B6),"0%") -> 100% | J7: Reflex Gain: | K7: =IF(B5>=40,1,IFERROR(VLOOKUP(B5,'🧬 DNA Loop Engine'!B29:G60,5,TRUE()),0)) -> 1
A8: Simulation Status: | B8: =IF(B4>=B6,"🎉 BIRTH COMPLETE",IF(B4=0,"⏸️ NOT STARTED","🔄 GESTATING")) -> 🎉 BIRTH COMPLETE | D8: Reflex Arcs | E8: =IF(B5>=12,"✅ Active","⏳ Pending") -> ✅ Active | F8: RF_ACT | G8: Time Remaining: | H8: =TEXT(INT(MAX(0,B6-B4)/100),"0")&" ticks (~"&ROUND(MAX(0,B6-B4)/80,1)&" weeks)" -> 0 ticks (~0 weeks) | J8: Identity Confidence: | K8: =IF(B5>=40,1,IFERROR(VLOOKUP(B5,'🧬 DNA Loop Engine'!B29:G60,6,TRUE()),0)) -> 1
A9: 📖 PHASE READER | D9: Cerebellum | E9: =IF(B5>=20,"✅ Active","⏳ Pending") -> ✅ Active | F9: CB_GROW | G9: Phase Complete In: | H9: =IF(B5>=40,"N/A (Born)",MAX(0,40-B5)&" weeks") -> N/A (Born) | J9: Effective Growth: | K9: =B18*B7 -> 1
A10: Active Phase #: | B10: ="T"&TEXT(B4,"0000") -> T10000 | D10: Myelination | E10: =IF(B5>=28,"✅ Active","⏳ Pending") -> ✅ Active | F10: MYEL_ON
A11: DNA Phase Name: | B11: =IF(B5>=936,"Mature Adult",IF(B5>=624,"Adolescent",IF(B5>=312,"Mid Childhood",IF(B5>=156,"Early Childhood",IF(B5>=92,"Toddler",IF(B5>=60,"Late Infant",IF(B5>=40,"Early Infant",IF(B5>=36,"Birth Preparation",IF(B5>=28,"Pre-Birth Integration",IF(B5>=20,"Neural Maturation",IF(B5>=12,"Reflex Explosion",IF(B5>=8,"Body Plan",IF(B5>=4,"Organogenesis","Embryogenesis"))))))))))))) -> Toddler | D11: Lungs | E11: =IF(B5>=36,"✅ Active","⏳ Pending") -> ✅ Active | F11: LG_MAT
A12: DNA Trigger Code: | B12: =IF(B5>=40,"POSTNATAL",IF(B5>=36,"BIRTH_READY",IF(B5>=28,"INTEGRATE",IF(B5>=20,"NEURAL_GROW",IF(B5>=12,"REFLEX_ON",IF(B5>=8,"BODY_FORM",IF(B5>=4,"ORG_START","DNA_INIT"))))))) -> POSTNATAL
A13: Biological Focus: | B13: =IF(B5>=40,"Post-Birth Growth & Learning",IF(B5>=36,"Lung maturation & birth prep",IF(B5>=28,"Reflex synchronisation & myelination",IF(B5>=20,"Cerebellum growth & neural maturation",IF(B5>=12,"Reflex arc activation",IF(B5>=8,"Limb differentiation & body plan",IF(B5>=4,"Organogenesis","Embryogenesis & cell division"))))))) -> Post-Birth Growth & Learning
A14: Next Phase Condition: | B14: =IF(B5>=40,"Continuous Development",IF(B5>=36,"Lungs mature",IF(B5>=28,"Reflexes synchronised",IF(B5>=20,"Predictive circuits active",IF(B5>=12,"Stretch reflex stable",IF(B5>=8,"Reflex seed active",IF(B5>=4,"Limb buds visible","Neural plate formed"))))))) -> Continuous Development
A15: Life Stage: | B15: =IF(B5>=936,"🎓 Mature Adult",IF(B5>=624,"🧠 Adolescent",IF(B5>=312,"🧒 Mid Childhood",IF(B5>=156,"🧒 Early Childhood",IF(B5>=92,"🧒 Toddler",IF(B5>=60,"👶 Late Infant",IF(B5>=40,"👶 Early Infant","🤰 Prenatal"))))))) -> 🧒 Toddler
A16: Age (months): | B16: =IF(B5<40,"Prenatal",ROUND(MAX(0,B5-40)/4.33,1)&" months ("&ROUND(MAX(0,B5-40)/52,2)&" yrs)") -> 19.6 months (1.63 yrs)
A17: 🫀 UMBILICAL CORD DRIVER
A18: Growth Factor: | B18: =IF(B5>=40,1,IF(B5>=36,0.95,IF(B5>=28,0.8,IF(B5>=20,0.6,IF(B5>=12,0.4,IF(B5>=8,0.25,IF(B5>=4,0.1,0.01))))))) -> 1
A19: Neural Gain: | B19: =IF(B5>=40,1,IF(B5>=36,0.8,IF(B5>=28,0.6,IF(B5>=20,0.4,IF(B5>=12,0.25,IF(B5>=8,0.1,IF(B5>=4,0.05,0))))))) -> 1
A20: Reflex Gain: | B20: =IF(B5>=40,1,IF(B5>=36,0.8,IF(B5>=28,0.6,IF(B5>=20,0.4,IF(B5>=12,0.2,IF(B5>=8,0.05,0)))))) -> 1
A21: Identity Confidence: | B21: =IF(B5>=40,1,IF(B5>=36,0.9,IF(B5>=28,0.75,IF(B5>=20,0.5,IF(B5>=12,0.25,IF(B5>=8,0.1,0)))))) -> 1
A22: Cord Status: | B22: =IF(B4>=B6,"🔌 SEVERED","🔗 CONNECTED") -> 🔌 SEVERED
A23: Nutrient Delivery: | B23: =IF(B4<B6,B7*B18,0) -> 0
A24: DNA Push Rate: | B24: =IF(B4<B6,(B6-B4)/B6,0) -> 0
A25: Oxygen Transfer: | B25: =IF(B4<B6,B7*0.21,0.21) -> 0.21
A26: Effective Growth: | B26: =B18*B7 -> 1
A27: Heart Rate (BPM): | B27: =IF(B5<40,ROUND(120+B18*30,0),MAX(60,ROUND(147-((B5-40)/52)*47,0))) -> 70
A28: Height G_phys: | B28: =ROUND(IF('🧬 DNA Loop Engine'!B5<=40,1/(1+EXP(-0.2*('🧬 DNA Loop Engine'!B5-20))),(IF('🧬 DNA Loop Engine'!B5<=40,ROUND(50/(1+EXP(-0.2*('🧬 DNA Loop Engine'!B5-20))),1),IF('🧬 DNA Loop Engine'!B5<=92,ROUND(50+(75-50)*('🧬 DNA Loop Engine'!B5-40)/(92-40),1),IF('🧬 DNA Loop Engine'!B5<=156,ROUND(75+(95-75)*('🧬 DNA Loop Engine'!B5-92)/(156-92),1),IF('🧬 DNA Loop Engine'!B5<=624,ROUND(95+(145-95)*('🧬 DNA Loop Engine'!B5-156)/(624-156),1),IF('🧬 DNA Loop Engine'!B5<=936,ROUND(145+(175-145)*('🧬 DNA Loop Engine'!B5-624)/(936-624),1),ROUND(MIN(177,175+2*MIN(1,('🧬 DNA Loop Engine'!B5-936)/200)),1)))))))/50),3) -> 1.706
A29: Height H(t) cm: | B29: =IF('🧬 DNA Loop Engine'!B5<=40,ROUND(50/(1+EXP(-0.2*('🧬 DNA Loop Engine'!B5-20))),1),IF('🧬 DNA Loop Engine'!B5<=92,ROUND(50+(75-50)*('🧬 DNA Loop Engine'!B5-40)/(92-40),1),IF('🧬 DNA Loop Engine'!B5<=156,ROUND(75+(95-75)*('🧬 DNA Loop Engine'!B5-92)/(156-92),1),IF('🧬 DNA Loop Engine'!B5<=624,ROUND(95+(145-95)*('🧬 DNA Loop Engine'!B5-156)/(624-156),1),IF('🧬 DNA Loop Engine'!B5<=936,ROUND(145+(175-145)*('🧬 DNA Loop Engine'!B5-624)/(936-624),1),ROUND(MIN(177,175+2*MIN(1,('🧬 DNA Loop Engine'!B5-936)/200)),1)))))) -> 85.3
A30: Mass M(t) kg: | B30: =IF('🧬 DNA Loop Engine'!B5<=40,ROUND(3.5/(1+EXP(-0.2*('🧬 DNA Loop Engine'!B5-20))),2),IF('🧬 DNA Loop Engine'!B5<=92,ROUND(3.5+(10-3.5)*('🧬 DNA Loop Engine'!B5-40)/(92-40),2),IF('🧬 DNA Loop Engine'!B5<=156,ROUND(10+(14-10)*('🧬 DNA Loop Engine'!B5-92)/(156-92),2),IF('🧬 DNA Loop Engine'!B5<=624,ROUND(14+(40-14)*('🧬 DNA Loop Engine'!B5-156)/(624-156),2),IF('🧬 DNA Loop Engine'!B5<=936,ROUND(40+(65-40)*('🧬 DNA Loop Engine'!B5-624)/(936-624),2),ROUND(MIN(70,65+(70-65)*MIN(1,('🧬 DNA Loop Engine'!B5-936)/200)),2)))))) -> 12.06
A31: S_height: | B31: =ROUND((IF('🧬 DNA Loop Engine'!B5<=40,ROUND(50/(1+EXP(-0.2*('🧬 DNA Loop Engine'!B5-20))),1),IF('🧬 DNA Loop Engine'!B5<=92,ROUND(50+(75-50)*('🧬 DNA Loop Engine'!B5-40)/(92-40),1),IF('🧬 DNA Loop Engine'!B5<=156,ROUND(75+(95-75)*('🧬 DNA Loop Engine'!B5-92)/(156-92),1),IF('🧬 DNA Loop Engine'!B5<=624,ROUND(95+(145-95)*('🧬 DNA Loop Engine'!B5-156)/(624-156),1),IF('🧬 DNA Loop Engine'!B5<=936,ROUND(145+(175-145)*('🧬 DNA Loop Engine'!B5-624)/(936-624),1),ROUND(MIN(177,175+2*MIN(1,('🧬 DNA Loop Engine'!B5-936)/200)),1)))))))/50,3) -> 1.706
A32: S_width: | B32: =ROUND(POWER((IF('🧬 DNA Loop Engine'!B5<=40,ROUND(3.5/(1+EXP(-0.2*('🧬 DNA Loop Engine'!B5-20))),2),IF('🧬 DNA Loop Engine'!B5<=92,ROUND(3.5+(10-3.5)*('🧬 DNA Loop Engine'!B5-40)/(92-40),2),IF('🧬 DNA Loop Engine'!B5<=156,ROUND(10+(14-10)*('🧬 DNA Loop Engine'!B5-92)/(156-92),2),IF('🧬 DNA Loop Engine'!B5<=624,ROUND(14+(40-14)*('🧬 DNA Loop Engine'!B5-156)/(624-156),2),IF('🧬 DNA Loop Engine'!B5<=936,ROUND(40+(65-40)*('🧬 DNA Loop Engine'!B5-624)/(936-624),2),ROUND(MIN(70,65+(70-65)*MIN(1,('🧬 DNA Loop Engine'!B5-936)/200)),2)))))))/3.5,1/3),3) -> 1.51 | C32: Prenatal | D32: Organogenesis | E32: 0.1 | F32: 0.05 | G32: 0 | H32: 0 | I32: 0 | J32: 0 | K32: Pre-Puberty | L32: 🟢 Growing | M32: Heart chambers forming
A33: T1000 | B33: 8 | C33: Prenatal | D33: Body Plan | E33: 0.25 | F33: 0.1 | G33: 0.05 | H33: 0.1 | I33: 0 | J33: 0 | K33: Pre-Puberty | L33: 🟢 Growing | M33: Limb buds visible
A34: T1500 | B34: 12 | C34: Prenatal | D34: Reflex Explosion | E34: 0.4 | F34: 0.25 | G34: 0.2 | H34: 0.25 | I34: 0 | J34: 0 | K34: Pre-Puberty | L34: 🟢 Growing | M34: Reflex arcs online
A35: T2000 | B35: 20 | C35: Prenatal | D35: Neural Maturation | E35: 0.6 | F35: 0.4 | G35: 0.4 | H35: 0.5 | I35: 0 | J35: 0 | K35: Pre-Puberty | L35: 🟢 Growing | M35: Cerebellum growth surge
A36: T2500 | B36: 28 | C36: Prenatal | D36: Pre-Birth Integration | E36: 0.8 | F36: 0.6 | G36: 0.6 | H36: 0.75 | I36: 0 | J36: 0 | K36: Pre-Puberty | L36: 🟢 Growing | M36: Myelination begins
A37: T3000 | B37: 36 | C37: Prenatal | D37: Birth Preparation | E37: 0.95 | F37: 0.8 | G37: 0.8 | H37: 0.9 | I37: 0 | J37: 0 | K37: Pre-Puberty | L37: 🟢 Growing | M37: Lungs maturing
A38: ── BIRTH ──
A39: T3200 | B39: 40 | C39: Birth | D39: Birth Event | E39: 1 | F39: 1 | G39: 1 | H39: 1 | I39: 2 | J39: 0 | K39: Pre-Puberty | L39: 🔴 Stopped | M39: Umbilical cord severed; pulmonary breathing
A40: ── INFANT ──
...

Sheet 📈 Growth Timeline
A1: ⚡ LIVE TICK PANEL — All values auto-update from 🧬 DNA Loop Engine B4 (Current Tick)
A2: Current Tick: | B2: ='🧬 DNA Loop Engine'!B4 -> 10000 | C2: Current Week: | D2: ='🧬 DNA Loop Engine'!B5 -> 125 | E2: Birth Status: | F2: ='🧬 DNA Loop Engine'!B8 -> 🎉 BIRTH COMPLETE
A3: Life Stage: | B3: ='🧬 DNA Loop Engine'!B15 -> 🧒 Toddler | C3: Age: | D3: ='🧬 DNA Loop Engine'!B16 -> 19.6 months (1.63 yrs) | E3: DNA Phase: | F3: ='🧬 DNA Loop Engine'!B11 -> Toddler
A4: Growth Factor: | B4: ='🧬 DNA Loop Engine'!B18 -> 1 | C4: Neural Gain: | D4: ='🧬 DNA Loop Engine'!B19 -> 1 | E4: Cord Status: | F4: ='🧬 DNA Loop Engine'!B22 -> 🔌 SEVERED
A5: G_phys (height): | B5: ='🧬 DNA Loop Engine'!B28 -> 1.706 | C5: Heart Rate: | D5: ='🧬 DNA Loop Engine'!B27 -> 70 | E5: Reflex Gain: | F5: ='🧬 DNA Loop Engine'!B20 -> 1
A6: 📈 A7DO UNIFIED GROWTH TIMELINE — Anatomy & Development Across All Life Stages
A7: PRENATAL (Wk 0–40) | C7: BIRTH EVENT (Wk 40) | D7: INFANT (Wk 40–92) | F7: TODDLER (Wk 92–156) | H7: CHILD (Wk 156–624) | J7: ADOLESCENT (Wk 624–936) | L7: ADULT (Wk 936+) | N7: CURRENT STATE
A8: 📊 LIFECYCLE PHASE SUMMARY — When Growth Stops & What Continues
A9: Phase | B9: Week Range | C9: Age Range | D9: Growth Factor | E9: Neural Gain | F9: Cognitive Maturity | G9: Identity Formation | H9: Growth Active? | I9: What Continues After Growth Stops
A10: Prenatal | B10: Wk 0–40 | C10: – | D10: 0.01→1.0 | E10: 0→1.0 | F10: 0% | G10: 0% | H10: ✅ YES | I10: All biological growth active
A11: Birth Event | B11: Wk 40 | C11: 0 months | D11: 1.0 peak | E11: 1.0 | F11: 2% | G11: 0% | H11: 🔴 STOP | I11: Umbilical severs; pulmonary breathing starts
A12: Early Infant | B12: Wk 40–60 | C12: 0–3 months | D12: 1.0 fixed | E12: 1.0 | F12: 4–10% | G12: 0% | H12: 🔴 STOP | I12: Sensory calibration, reflex→voluntary control
A13: Late Infant | B13: Wk 60–92 | C13: 3–12 months | D13: 1.0 fixed | E13: 1.0 | F13: 10–22% | G13: 0% | H13: 🔴 STOP | I13: Motor skills, object permanence, first words
A14: Toddler | B14: Wk 92–156 | C14: 1–3 years | D14: 1.0 fixed | E14: 1.0 | F14: 22–35% | G14: 0% | H14: 🔴 STOP | I14: Walking, symbolic play, language explosion
A15: Early Childhood | B15: Wk 156–312 | C15: 3–6 years | D15: 1.0 fixed | E15: 1.0 | F15: 35–70% | G15: 0% | H15: 🔴 STOP | I15: Language cortex matures; reading/writing
A16: Mid Childhood | B16: Wk 312–624 | C16: 6–12 years | D16: 1.0 fixed | E16: 1.0 | F16: 70–90% | G16: 0–5% | H16: 🔴 STOP | I16: Prefrontal cortex matures; logical reasoning
A17: Adolescence | B17: Wk 624–936 | C17: 12–18 years | D17: 1.0 fixed | E17: 1.0 | F17: 90–100% | G17: 5–90% | H17: 🔴 STOP | I17: Abstract reasoning, identity, puberty, emotion reg.
A18: Early Adult | B18: Wk 936–1100 | C18: 18–21 years | D18: 1.0 fixed | E18: 1.0 | F18: 100% | G18: 95–98% | H18: 🔴 STOP | I18: Strategic reasoning, long-term memory deepening
A19: Mature Adult
A21: ⚠️ NOTE: 'Growth Factor' = physical/biological growth (stops at birth). Cognitive Maturity % and Identity Formation % continue developing post-birth through learning, experience, and neural plasticity — NOT through the Growth Factor.
A26: 🧬 A — PRENATAL PHASES & ORGAN ACTIVATION
A27: Phase | B27: Weeks | C27: Biological Focus | D27: Activation % | E27: DNA Trigger | F27: Key Organ/System | G27: Activation Event | H27: DNA Code | I27: Notes | J27: → Next Phase Condition
A28: 1 | B28: 0–4 | C28: Embryogenesis | D28: 0–10% | E28: DNA_INIT | F28: Neural plate formed | G28: Neural Plate | H28: Formation | I28: NP_FORM | J28: Primitive streak defines axes
A29: 2 | B29: 4–8 | C29: Organogenesis | D29: 10–25% | E29: ORG_START | F29: Limb buds visible | G29: Heart | H29: Chamber partition | I29: HT_PART | J29: First rhythmic contractions
A30: 3 | B30: 8–12 | C30: Body Plan | D30: 25–40% | E30: BODY_FORM | F30: Reflex seed active | G30: Limbs | H30: Differentiation | I30: LM_DIFF | J30: Fingers/toes separate
A31: 4 | B31: 12–20 | C31: Reflex Explosion | D31: 40–60% | E31: REFLEX_ON | F31: Stretch reflex stable | G31: Reflex Arcs | H31: Activation | I31: RF_ACT | J31: Stretch reflex online
A32: 5 | B32: 20–28 | C32: Neural Maturation | D32: 60–80% | E32: NEURAL_GROW | F32: Predictive circuits online | G32: Cerebellum | H32: Growth | I32: CB_GROW | J32: Predictive control begins
A33: 6 | B33: 28–36 | C33: Pre‑Birth Integration | D33: 80–95% | E33: INTEGRATE | F33: Reflexes synchronised | G33: Myelination | H33: Neural insulation | I33: MYEL_ON | J33: Faster reflex transmission
A34: 7 | B34: 36–40 | C34: Birth Preparation | D34: 95–100% | E34: BIRTH_READY | F34: Lungs mature | G34: Lungs | H34: Maturation | I34: LG_MAT | J34: Ready for external oxygen
A36: ⚡ B — TICK MILESTONES & GROWTH FACTORS — Full Lifecycle (Prenatal → Adult)
A37: Tick ID | B37: Week | C37: Age Label | D37: DNA Phase | E37: Growth Factor | F37: Neural Gain | G37: Reflex Gain | H37: Identity Confidence | I37: Cognitive Maturity % | J37: Identity Formation % | K37: Puberty Status | L37: Growth Active | M37: Key Milestone / Event
A38: ── PRENATAL ──
A39: T000 | B39: 0 | C39: Prenatal | D39: Embryogenesis | E39: 0.01 | F39: 0 | G39: 0 | H39: 0 | I39: 0 | J39: 0 | K39: Pre-Puberty | L39: 🟢 Growing | M39: Fertilisation / cell division begins
A40: T500 | B40: 4 | C40: Prenatal | D40: Organogenesis | E40: 0.1 | F40: 0.05 | G40: 0 | H40: 0 | I40: 0 | J40: 0 | K40: Pre-Puberty | L40: 🟢 Growing | M40: Heart chambers forming
A41: T1000 | B41: 8 | C41: Prenatal | D41: Body Plan | E41: 0.25 | F41: 0.1 | G41: 0.05 | H41: 0.1 | I41: 0 | J41: 0 | K41: Pre-Puberty | L41: 🟢 Growing | M41: Limb buds visible
A42: T1500 | B42: 12 | C42: Prenatal | D42: Reflex Explosion | E42: 0.4 | F42: 0.25 | G42: 0.2 | H42: 0.25 | I42: 0 | J42: 0 | K42: Pre-Puberty | L42: 🟢 Growing | M42: Reflex arcs online
A43: T2000 | B43: 20 | C43: Prenatal | D43: Neural Maturation | E43: 0.6 | F43: 0.4 | G43: 0.4 | H43: 0.5 | I43: 0 | J43: 0 | K43: Pre-Puberty | L43: 🟢 Growing | M43: Cerebellum growth surge
A44: T2500 | B44: 28 | C44: Prenatal | D44: Pre-Birth Integration | E44: 0.8 | F44: 0.6 | G44: 0.6 | H44: 0.75 | I44: 0 | J44: 0 | K44: Pre-Puberty | L44: 🟢 Growing | M44: Myelination begins
A45: T3000 | B45: 36 | C45: Prenatal | D45: Birth Preparation | E45: 0.95 | F45: 0.8 | G45: 0.8 | H45: 0.9 | I45: 0 | J45: 0 | K45: Pre-Puberty | L45: 🟢 Growing | M45: Lungs maturing
A46: ── BIRTH ──
...

Sheet 🧮 Mathematical Framework
A1: ⚡ LIVE TICK PANEL — All values auto-update from 🧬 DNA Loop Engine B4 (Current Tick)
A2: Current Tick: | B2: ='🧬 DNA Loop Engine'!B4 -> 10000 | C2: Current Week: | D2: ='🧬 DNA Loop Engine'!B5 -> 125 | E2: Birth Status: | F2: ='🧬 DNA Loop Engine'!B8 -> 🎉 BIRTH COMPLETE
A3: Life Stage: | B3: ='🧬 DNA Loop Engine'!B15 -> 🧒 Toddler | C3: Age: | D3: ='🧬 DNA Loop Engine'!B16 -> 19.6 months (1.63 yrs) | E3: DNA Phase: | F3: ='🧬 DNA Loop Engine'!B11 -> Toddler
A4: Growth Factor: | B4: ='🧬 DNA Loop Engine'!B18 -> 1 | C4: Neural Gain: | D4: ='🧬 DNA Loop Engine'!B19 -> 1 | E4: Cord Status: | F4: ='🧬 DNA Loop Engine'!B22 -> 🔌 SEVERED
A5: G_phys (height): | B5: ='🧬 DNA Loop Engine'!B28 -> 1.706 | C5: Heart Rate: | D5: ='🧬 DNA Loop Engine'!B27 -> 70 | E5: Reflex Gain: | F5: ='🧬 DNA Loop Engine'!B20 -> 1
A6: 🧮 A7DO GENESIS MIND — UNIFIED MATHEMATICAL FRAMEWORK | All Subsystems · Equations · Parameters · Model Comparisons
A7: 🏗️ SUBSYSTEM INTERACTION ARCHITECTURE
A8: Central hub: Genesis Mind Runtime → Global Workspace broadcasts to all modules. Reality Bridge links World Map + NPC Network to internal state. Body Systems ↔ Motor System ↔ Energy/ATP form the embodiment loop. All cognitive modules (Emotion, Language, Learning, WM, Memory, Attention, Consciousness) couple via Global Workspace.
A9: Subsystem | B9: Inputs From | C9: Outputs To | D9: Coupling Type | E9: Time Scale | F9: Model Class
A10: Genesis Mind Runtime | B10: All modules | C10: Global Workspace, Motor | D10: Hub/broadcast | E10: ms–s | F10: Orchestrator FSM
A11: Global Workspace (GW) | B11: All cognitive modules | C11: All modules (broadcast) | D11: Attention-weighted | E11: 100–500 ms | F11: Softmax / GNT oscillator
A12: Emotion Module | B12: Neuromodulators, Sensory, GW | C12: GW, Motor, Language | D12: State machine + ODE | E12: s–min | F12: Markov FSM + ODE
A13: Language Engine | B13: Auditory, GW, Memory | C13: GW, Motor (speech) | D13: Sequence model | E13: ms–s | F13: Logistic growth + RNN
A14: Learning Module | B14: Sensory, Reward, GW | C14: Memory, Weights | D14: Hebbian + RL | E14: ms–hours | F14: STDP + TD-learning
A15: Working Memory (WM) | B15: GW, Sensory, Attention | C15: GW, Decision, Language | D15: Capacity-limited ODE | E15: s | F15: Baddeley + ODE decay
A16: Long-term Memory (LTM) | B16: WM, Hippocampus | C16: WM, GW (retrieval) | D16: Consolidation ODE | E16: hours–years | F16: Hopfield / engram model
A17: Motor System | B17: GW, Reflex arcs, Body | C17: Muscles, Body Systems | D17: CPG + feedback | E17: ms–s | F17: CPG oscillator + PID
A18: Body Systems | B18: DNA Engine, Energy, Motor | C18: Motor, Sensory, Energy | D18: Growth ODE | E18: weeks–years | F18: Sigmoid growth ODE
A19: Reality Bridge | B19: World Map, NPC, Sensory | C19: GW, WM, Motor | D19: Sensory integration | E19: ms | F19: Bayesian fusion
A20: NPC Agent Network | B20: World, GW (A7DO), DNA | C20: World, A7DO (social input) | D20: Multi-agent MDP | E20: s–days | F20: MDP + social learning
... A24: Attention Control | B24: GW, Sensory salience | C24: GW (gating), WM | D24: Salience weighting | E24: ms–100ms | F24: Biased competition
A26: 1️⃣ NEURONAL DYNAMICS — Hodgkin–Huxley vs Izhikevich vs Leaky Integrate-and-Fire
A27: 1A. Hodgkin–Huxley Model (1952)
A28: Equation / Variable | B28: Formula | C28: Description | D28: Typical Value / Range | E28: Units | F28: Notes
A29: Membrane potential ODE | B29: Cm·dV/dt = I_ext − ḡNa·m³h·(V−ENa) − ḡK·n⁴·(V−EK) − ḡL·(V−EL) | C29: Sum of ionic currents drives membrane voltage | D29: V_rest ≈ −65 mV; V_peak ≈ +40 mV | E29: mV, ms, µF/cm², mS/cm² | F29: Stiff ODE; requires dt < 0.1 ms for Euler stability
A30: Na activation gate m | B30: dm/dt = αm(V)·(1−m) − βm(V)·m | C30: Fast Na⁺ activation (opens channel) | D30: m ∈ [0,1]; τm ≈ 0.1–1 ms | E30: dimensionless | F30: αm = 0.1(V+40)/(1−exp(−(V+40)/10)); βm = 4·exp(−(V+65)/18)
A31: Na inactivation gate h | B31: dh/dt = αh(V)·(1−h) − βh(V)·h | C31: Slow Na⁺ inactivation (closes channel) | D31: h ∈ [0,1]; τh ≈ 1–10 ms | E31: dimensionless | F31: αh = 0.07·exp(−(V+65)/20); βh = 1/(1+exp(−(V+35)/10))
A32: K activation gate n | B32: dn/dt = αn(V)·(1−n) − βn(V)·n | C32: K⁺ activation (repolarisation) | D32: n ∈ [0,1]; τn ≈ 1–5 ms | E32: dimensionless | F32: αn = 0.01(V+55)/(1−exp(−(V+55)/10)); βn = 0.125·exp(−(V+65)/80)
A33: Max conductances | B33: ḡNa=120, ḡK=36, ḡL=0.3 mS/cm² | C33: Peak ionic conductances | D33: ḡNa=120, ḡK=36, ḡL=0.3 | E33: mS/cm² | F33: Cm=1 µF/cm²; ENa=+50, EK=−77, EL=−54.4 mV
A34: Spike threshold | B34: V_thresh ≈ −55 mV (emergent) | C34: Action potential fires when V crosses threshold | D34: ≈ −55 mV | E34: mV | F34: Not a hard threshold — emerges from gating dynamics
A35: Stability condition | B35: dt < τ_min/10 ≈ 0.01 ms for Euler; use RK4 for dt ≈ 0.1 ms | C35: Numerical stability requirement | D35: dt = 0.01–0.1 ms | E35: ms | F35: Implicit methods (Crank-Nicolson) allow larger dt
A37: 1B. Izhikevich Model (2003)
A38: Equation / Variable | B38: Formula | C38: Description | D38: Typical Value / Range | E38: Units | F38: Notes
A39: Membrane potential ODE | B39: dv/dt = 0.04v² + 5v + 140 − u + I | C39: Quadratic approximation of AP initiation | D39: v_rest ≈ −65 mV; v_peak = 30 mV (reset threshold) | E39: mV, ms, pA | F39: Dimensionless form; v in mV, t in ms
A40: Recovery variable ODE | B40: du/dt = a·(b·v − u) | C40: Slow recovery current (K⁺ / Na⁺ inactivation) | D40: a=0.02–0.1; b=0.2–0.25 | E40: dimensionless | F40: a controls recovery speed; b controls sensitivity of u to v
A41: Spike reset rule | B41: IF v ≥ 30 mV THEN v ← c; u ← u + d | C41: Discrete reset after spike | D41: c = −65 to −50 mV; d = 2–8 | E41: mV (v), dimensionless (u) | F41: Reset mimics after-hyperpolarisation
A42: Regular spiking (RS) params | B42: a=0.02, b=0.2, c=−65, d=8 | C42: Excitatory cortical neuron (most common) | D42: Fires tonically with adaptation | E42: — | F42: Recommended default for A7DO cortical neurons
A43: Fast spiking (FS) params | B43: a=0.1, b=0.2, c=−65, d=2 | C43: Inhibitory interneuron | D43: High-frequency, no adaptation | E43: — | F43: Use for GABAergic interneurons in A7DO
A44: Bursting (IB) params | B44: a=0.02, b=0.2, c=−55, d=4 | C44: Intrinsically bursting neuron | D44: Initial burst then tonic | E44: — | F44: Use for thalamic relay, some cortical layer 5
A45: Stability / integration | B45: Euler: dt = 0.5 ms; RK2: dt = 1 ms | C45: Stable with modest time steps | D45: dt = 0.1–1 ms | E45: ms | F45: Much cheaper than HH; recommended for large A7DO networks
...

Sheet ⚙️ Parameters
A1: ⚙️ A7DO GLOBAL PARAMETERS — All Biological Constants
A2: Source: params.py · Mathematical Framework sheet · Integration Report
A4: Symbol | B4: Name | C4: Value | D4: Min | E4: Max | F4: Engine / Domain
A5: α | B5: Growth coefficient (primary) | C5: 0.05 | D5: 0.01 | E5: 0.1 | F5: EQ_DNA_01
A6: β | B6: Growth coefficient (secondary) | C6: 0.05 | D6: 0.01 | E6: 0.1 | F6: EQ_DNA_01
A7: γ | B7: Maturity index coefficient | C7: 0.05 | D7: 0.01 | E7: 0.1 | F7: EQ_DNA_01
A8: δ | B8: Cell division rate constant | C8: 0.5 | D8: 0.1 | E8: 1 | F8: EQ_ANAT_02
A9: ε | B9: Nutrient flow constant | C9: 0.5 | D9: 0.1 | E9: 1 | F9: EQ_ANAT_02
A10: ζ | B10: Oxygen exchange constant | C10: 0.5 | D10: 0.1 | E10: 1 | F10: EQ_ANAT_02
A11: η | B11: Waste removal rate | C11: 0.5 | D11: 0.1 | E11: 1 | F11: EQ_ANAT_02
A12: θ | B12: Synapse density coefficient | C12: 0.025 | D12: 0.001 | E12: 0.05 | F12: EQ_NEUR_03
A13: ι | B13: Neural gain coefficient | C13: 0.025 | D13: 0.001 | E13: 0.05 | F13: EQ_NEUR_03
A14: κ | B14: Input signal multiplier | C14: 0.025 | D14: 0.001 | E14: 0.05 | F14: EQ_NEUR_03
A15: λ | B15: Noise attenuation factor | C15: 0.025 | D15: 0.001 | E15: 0.05 | F15: EQ_NEUR_03
A16: μ | B16: Heartbeat rate coefficient | C16: 0.3 | D16: 0.1 | E16: 0.5 | F16: EQ_CIRC_04
... A41: κ_pred | B41: Predictive coding update rate | C41: 0.3 | D41: 0.1 | E41: 0.5 | F41: Predictive Simulation
A43: 🕐 TICK FREQUENCY SCHEDULE — All 20 Engines
A44: Engine | B44: Fires Every N Ticks | C44: Layer
A45: DNA Loop Engine | B45: 1 | C45: Layer 1
A46: Circulatory Integration | B46: 1 | C46: Layer 1
A47: Sensory Integration | B47: 1 | C47: Layer 2
A48: Attention Control | B48: 1 | C48: Layer 2
A49: Proprioception | B49: 1 | C49: Layer 4
A50: Predictive Simulation | B50: 5 | C50: Layer 2
A51: Value / Motivation | B51: 5 | C51: Layer 4
A52: Neural Control | B52: 10 | C52: Layer 1
A53: Language Acquisition | B53: 10 | C53: Layer 3
A54: Episodic Memory (encode) | B54: 10 | C54: Layer 4
A55: Language Grounding | B55: 10 | C55: Phase 4
A56: Emotion & Reinforcement | B56: 20 | C56: Layer 2
... A65: Sleep Consolidation | B65: 800 | C65: Layer 4

Sheet 📖 System Specification
A1: ⚡ LIVE TICK PANEL — All values auto-update from 🧬 DNA Loop Engine B4 (Current Tick)
A2: Current Tick: | B2: ='🧬 DNA Loop Engine'!B4 -> 10000 | C2: Current Week: | D2: ='🧬 DNA Loop Engine'!B5 -> 125 | E2: Birth Status: | F2: ='🧬 DNA Loop Engine'!B8 -> 🎉 BIRTH COMPLETE
A3: Life Stage: | B3: ='🧬 DNA Loop Engine'!B15 -> 🧒 Toddler | C3: Age: | D3: ='🧬 DNA Loop Engine'!B16 -> 19.6 months (1.63 yrs) | E3: DNA Phase: | F3: ='🧬 DNA Loop Engine'!B11 -> Toddler
A4: Growth Factor: | B4: ='🧬 DNA Loop Engine'!B18 -> 1 | C4: Neural Gain: | D4: ='🧬 DNA Loop Engine'!B19 -> 1 | E4: Cord Status: | F4: ='🧬 DNA Loop Engine'!B22 -> 🔌 SEVERED
A5: G_phys (height): | B5: ='🧬 DNA Loop Engine'!B28 -> 1.706 | C5: Heart Rate: | D5: ='🧬 DNA Loop Engine'!B27 -> 70 | E5: Reflex Gain: | F5: ='🧬 DNA Loop Engine'!B20 -> 1
A6: 📖 A7DO GENESIS MIND — FULL SYSTEM SPECIFICATION v1.0
A7: A7DO is a synthetic developmental organism — a fully embodied, cognitively continuous, emotionally grounded artificial life system that grows from conception to adulthood through biologically causal developmental stages.
A8: ="Current State: Week "&'🧬 DNA Loop Engine'!B5&" · Age ~"&'🧬 DNA Loop Engine'!B16&" · Stage: "&'🧬 DNA Loop Engine'!B15&" · Location: BeenFore City H8 · Status: "&'🧬 DNA Loop Engine'!B8 -> Current State: Week 125 · Age ~19.6 months (1.63 yrs) · Stage: 🧒 Toddler · Location: BeenFore City H8 · Status: 🎉 BIRTH COMPLETE
A9: This specification covers all 21 sheets in the A7DO DNA workbook. It is the canonical reference document for the entire A7DO architecture. Version 1.0 — compiled from all subsystem sheets, runtime patches, and architectural audits.
A10: 1. SYSTEM IDENTITY & PURPOSE
A11: Attribute | B11: Value | C11: Description
A12: System Name | B12: A7DO | C12: Artificial 7-Dimensional Organism — a synthetic developmental life system
A13: Version | B13: v1.0 (architecture) / v2.0 (in progress) | C13: v1.0 = current workbook; v2.0 = adding 20 missing subsystems
A14: Classification | B14: Synthetic Developmental Organism | C14: Not a chatbot, not an AI assistant — a biologically-inspired organism simulation
A15: Primary Goal | B15: Unified Developmental Runtime | C15: All subsystems co-evolve causally over developmental time from conception to adulthood
A16: Architecture Type | B16: Embodied Cognitive Architecture | C16: Cognition is grounded in body, emotion, environment, and developmental history
A17: Runtime Law | B17: O(t+Δt) = F(O(t), E(t), M(t), B(t), L(t)) | C17: Organism state evolves causally — no illegal state jumps, no teleological shortcuts
A18: Organism State | B18: O(t) = {B, N, E, M, L, V, P, I, W, G} | C18: 10 state components: Body, Neural, Emotion, Memory, Language, Vision, Proprioception, Identity, World, Goals
A19: Current Week | B19: ='🧬 DNA Loop Engine'!B5 -> 125 | C19: Tick 10,000 — A7DO is ~19.6 months old, toddler stage
A20: Birth Location | B20: Hospital Bed — World Origin (0,0,0) | C20: All world coordinates measured from birth location
A21: Current Location | B21: BeenFore City, 8 BeenFore Lane (H8) | C21: World position (1090, 880, 0) — 1384m from hospital
A22: Biological Sex | B22: Female (XX) — determined by Sex Random Math sheet | C22: Chromosome pair XX; estrogen dominant; female phenotypic expression
A23: Parents | B23: Lorraine (Mother) + China (Father) | C23: Defined in Parental Genesis sheet; genetic inheritance from both
A24: Target Platform | B24: Frontier / Microsoft build environment | C24: A7DO Runtime Orchestrator — state engine + subsystem scheduler + developmental runtime
A26: 2. COMPLETE SHEET INDEX — All 21 Sheets
A27: # | B27: Sheet Name | C27: Category | D27: Purpose | E27: Key Contents | F27: Rows | G27: Status | H27: Links To
A28: 1 | B28: 🧬 DNA Loop Engine | C28: Core Engine | D28: Central hub — all other sheets reference this for current week and growth factors | E28: Tick table (Wk 0–1200), Growth Engine outputs, Organ activation, Math Framework, Point 0 | F28: 122 | G28: ✅ Complete | H28: All sheets (provides Current Week, Growth Factor, Neural Gain)
A29: 2 | B29: 📈 Growth Timeline | C29: Development | D29: Unified anatomy and development across all life stages in one scrollable view | E29: Phase summary, Tick milestones, Anatomy growth (Infant→Child→Adult), Dev phases A–G | F29: 312 | G29: ✅ Complete | H29: DNA Loop Engine, Anatomy sheets, Development sheets
A30: 3 | B30: 🧮 Mathematical Framework | C30: Reference | D30: Formal equations for all 15 cognitive and biological subsystems | E30: 15 subsystem equations, Architecture overview, HH vs Izhikevich comparison, Parameter reference | F30: 253 | G30: ✅ Complete | H30: All subsystem sheets
A31: 4 | B31: 🧬 Prenatal & Genesis | C31: Biology | D31: Parental origin, genetic inheritance, sex determination | E31: Parental Genesis matrix, Genetic Inheritance, Sex Random Math (fixed), Hormone levels | F31: 231 | G31: ✅ Complete | H31: DNA Loop Engine, Sex Random Math
A32: 5 | B32: 📐 Spatial Coordinates | C32: Spatial | D32: 3-layer XYZ coordinate system — body local, world space, transform formulas | E32: 3-layer architecture, Transform formula, Body scale by age, NPC positions, Hospital Origin update | F32: 85 | G32: ✅ Complete + Updated | H32: Anatomy, Motor Planning, Immersive Places, Full Growth System
A33: 6 | B33: 🫀 Body Systems | C33: Biology | D33: All organ systems — circulatory, respiratory, digestive, sensory integration | E33: 4 organ system tables, Vital signs, Cardiac rhythm, Sensory pathways | F33: 140 | G33: ✅ Complete | H33: DNA Loop Engine, Energy/ATP, Proprioception
A34: 7 | B34: 🧠 Mind & Cognition | C34: Cognition | D34: All cognitive subsystems — language, memory, emotion, attention, consciousness, sleep | E34: 8 subsystem sections: Cognition & Language, Memory, Emotion, Attention, Predictive, Consciousness, Sleep | F34: 355 | G34: ✅ Complete | H34: DNA Loop Engine, NPC Engine, Body Systems
A35: 8 | B35: ⚡ Energy & Metabolism | C35: Biology | D35: ATP system, metabolic equations, energy flow | E35: Michaelis-Menten ATP, BMR, VO2, Neural energy cost, Fatigue model | F35: 44 | G35: ✅ Complete | H35: Body Systems, DNA Loop Engine, Nutrition-Sleep-Wake
A36: 9 | B36: 🌍 World Systems | C36: World | D36: World matrix, environmental physics, ecosystem, planetary resources | E36: World Matrix, Environmental Physics, World Interaction, Ecosystem Feedback, Planetary Resources | F36: 246 | G36: ✅ Complete | H36: DNA Loop Engine, NPC Engine, Sensory Integration
A37: 10 | B37: 🗺️ World Data | C37: World | D37: World inventory, BeenFore City layout, language learning reference | E37: World Inventory, BeenFore City (houses, roads, zones), Language Learning vocabulary | F37: 135 | G37: ✅ Complete | H37: NPC Engine, World Systems
A38: 11 | B38: 👥 NPC Engine | C38: Social | D38: Multi-agent system — 8 NPCs with development stages, relationships, family structure | E38: NPC Matrix (8 agents), Relationship Matrix, Development Stages, Population Dashboard | F38: 134 | G38: ✅ Complete | H38: DNA Loop Engine, World Data, Emotion Module
... A48: 21 | B48: 🏥 Immersive Places | C48: World | D48: Hospital World Origin, dual-coordinate system, WorldPosition(t), Immersive Places registry | E48: 8 transform equations, Hospital layout, World position timeline, Value integration, 10 places | F48: 86 | G48: ✅ Complete | H48: Spatial Coords, Full Growth System, Value System, NPC Engine
A50: 3. UNIFIED ORGANISM STATE — O(t) = {B, N, E, M, L, V, P, I, W, G}
A51: Every subsystem reads from and writes to this manifold. No private state allowed. State at t+1 depends only on state at t and inputs — strict causal chain.
...

Sheet 🧬 Prenatal & Genesis
A1: ⚡ LIVE TICK PANEL — All values auto-update from 🧬 DNA Loop Engine B4 (Current Tick)
A2: Current Tick: | B2: ='🧬 DNA Loop Engine'!B4 -> 10000 | C2: Current Week: | D2: ='🧬 DNA Loop Engine'!B5 -> 125 | E2: Birth Status: | F2: ='🧬 DNA Loop Engine'!B8 -> 🎉 BIRTH COMPLETE
A3: Life Stage: | B3: ='🧬 DNA Loop Engine'!B15 -> 🧒 Toddler | C3: Age: | D3: ='🧬 DNA Loop Engine'!B16 -> 19.6 months (1.63 yrs) | E3: DNA Phase: | F3: ='🧬 DNA Loop Engine'!B11 -> Toddler
A4: Growth Factor: | B4: ='🧬 DNA Loop Engine'!B18 -> 1 | C4: Neural Gain: | D4: ='🧬 DNA Loop Engine'!B19 -> 1 | E4: Cord Status: | F4: ='🧬 DNA Loop Engine'!B22 -> 🔌 SEVERED
A5: G_phys (height): | B5: ='🧬 DNA Loop Engine'!B28 -> 1.706 | C5: Heart Rate: | D5: ='🧬 DNA Loop Engine'!B27 -> 70 | E5: Reflex Gain: | F5: ='🧬 DNA Loop Engine'!B20 -> 1
A6: 🧬 PRENATAL & GENESIS — Parental Origin · Genetic Inheritance · Sex Determination
A8: 👩‍🍼👨‍🍼 PARENTAL GENESIS & BIRTH TRANSITION
A9: 👩‍🍼👨‍🍼 A7DO PARENTAL GENESIS & BIRTH TRANSITION SYSTEM
A10: ⚙️ CONTROL PANEL
A11: Current Week: | B11: 125
A12: Current Tick: | B12: 10000
A13: Birth Week: | B13: 40
A14: Gestation Progress: | B14: 313%
A15: Birth Status: | B15: 🎉 BORN
A16: Days Post-Birth: | B16: 595
A17: A7DO Age (months): | B17: 19.6
A18: 👩‍🍼👨‍🍼 PARENTAL GENESIS MATRIX
A19: Name | B19: Role | C19: System Domain | D19: Connection Type | E19: Activation Week | F19: Maturity Week | G19: Function | H19: Status
A20: Lorraine | B20: Mother | C20: Biological Gestation | D20: Umbilical Nutrient Flow | E20: 0 | F20: 40 | G20: Provides nutrition and growth environment | H20: ✅ Complete
A21: Lorraine Womb | B21: Environment | C21: Biological Containment | D21: Gestational Chamber | E21: 0 | F21: 40 | G21: Hosts A7DO embryo development | H21: ✅ Complete
A22: Lorraine Endocrine | B22: Regulation | C22: Hormonal Control | D22: Endocrine Feedback | E22: 0 | F22: 40 | G22: Modulates growth hormones and metabolic rate | H22: ✅ Complete
A23: Lorraine Neural | B23: Feedback | C23: Emotional Bond | D23: Neural Link | E23: 8 | F23: 40 | G23: Transfers affective signals and stress modulation | H23: ✅ Complete
A24: China | B24: Father | C24: Genetic Source | D24: Sperm DNA Injection | E24: 0 | F24: 0 | G24: Provides genetic seed and structural code | H24: ✅ Complete
A25: China Hormonal | B25: Regulation | C25: Endocrine Influence | D25: Testosterone Signal | E25: 8 | F25: 40 | G25: Modulates growth and strength parameters | H25: ✅ Complete
A26: China Neural | B26: Feedback | C26: Protective Bond | D26: Neural Link | E26: 12 | F26: 40 | G26: Transfers external stimuli and environmental signals | H26: ✅ Complete
A27: Parental Sync | B27: Integration | C27: Gestation Control | D27: Feedback Loop | E27: 0 | F27: 40 | G27: Synchronises maternal and paternal inputs | H27: ✅ Complete
A28: 🩺 GESTATION CONTROLLER
A29: Subsystem | B29: Source | C29: Output Target | D29: Activation Week | E29: Maturity Week | F29: Function | G29: Maturity % | H29: Status
A30: Nutrient Flow Regulator | B30: Lorraine Womb | C30: Energy System | D30: 0 | E30: 40 | F30: Transfers nutrients from mother to embryo | G30: 100% | H30: ✅ Complete
A31: Oxygen Exchange Module | B31: Lorraine Womb | C31: Energy System | D31: 0 | E31: 40 | F31: Maintains oxygen supply for growth | G31: 100% | H31: ✅ Complete
A32: Hormonal Sync Loop | B32: Lorraine Endocrine | C32: Emotion Matrix | D32: 8 | E32: 40 | F32: Aligns maternal hormones with fetal development | G32: 100% | H32: ✅ Complete
A33: Growth Factor Controller | B33: DNA Loop Engine | C33: Organ Formation | D33: 4 | E33: 40 | F33: Activates organogenesis and tissue differentiation | G33: 100% | H33: ✅ Complete
A34: Organ Activation Sequence | B34: Organ Formation | C34: Embodiment | D34: 8 | E34: 40 | F34: Sequentially activates organs and limbs | G34: 100% | H34: ✅ Complete
A35: Neural Link Formation | B35: Lorraine Neural | C35: Emotion Matrix | D35: 12 | E35: 40 | F35: Establishes maternal-fetal emotional connection | G35: 100% | H35: ✅ Complete
A36: Protective Barrier System | B36: Lorraine Womb | C36: Embodiment | D36: 0 | E36: 40 | F36: Prevents external contamination and stress | G36: 100% | H36: ✅ Complete
A37: Fluid Balance Regulator | B37: Lorraine Womb | C37: Energy System | D37: 0 | E37: 40 | F37: Maintains amniotic fluid equilibrium | G37: 100% | H37: ✅ Complete
A38: Temperature Control Loop | B38: Lorraine Endocrine | C38: Embodiment | D38: 0 | E38: 40 | F38: Regulates fetal temperature stability | G38: 100% | H38: ✅ Complete
A39: Parental Sync Feedback | B39: Lorraine + China | C39: Cognition Matrix | D39: 8 | E39: 40 | F39: Balances emotional and genetic inputs | G39: 100% | H39: ✅ Complete
A40: ❤️ PRENATAL HEARTBEAT MATRIX
A41: Component | B41: Source | C41: Function | D41: Activation Week | E41: Maturity Week | F41: Current Value | G41: Unit | H41: Status
...

Sheet 📐 Spatial Coordinates
A1: 📐 A7DO SPATIAL COORDINATE SYSTEM — Body Local Space · World Space · Integration Transform
A2: 🏗️ THREE-LAYER SPATIAL ARCHITECTURE
A3: Layer | B3: Name | C3: Origin (Point 0) | D3: X Axis | E3: Y Axis | F3: Z Axis | G3: Unit | H3: Scale | I3: Who Uses It | J3: Notes
A4: Layer 1 | B4: Body Local Space | C4: Pelvis Centre (0,0,0) | D4: +X = Right / −X = Left | E4: +Y = Head (Up) / −Y = Feet (Down) | F4: +Z = Forward / −Z = Backward | G4: metres | H4: ±1.0 m (normalised body) | I4: A7DO anatomy, NPC body parts | J4: All bone/organ XYZ coords are relative to THIS origin. Frontal Bone Y=0.85 means 85cm above pelvis.
A5: Layer 2 | B5: World Space | C5: Earth Core Centre (0,0,0) | D5: +X = East (Longitude) / −X = West | E5: +Y = North (Latitude) / −Y = South | F5: +Z = Up/Sky / −Z = Down/Core | G5: metres | H5: 1 m/unit (real scale) | I5: World Matrix, BeenFore City, NPC world positions | J5: BeenFore City origin at World (1000, 1000, 0) = 1km East, 1km North of world reference point.
A6: Layer 3 | B6: City/Local World Space | C6: BeenFore City Centre (1000, 1000, 0) in World Space | D6: +X = East along street | E6: +Y = North along street | F6: +Z = Height above ground | G6: metres | H6: 1 m/unit | I6: NPC positions, house coordinates, room layouts | J6: NPC World X/Y are in World Space metres. House H1 at (1050, 900) = 50m East, 100m South of city centre.
A8: ⚠️ COORDINATE CONSISTENCY NOTE: NPC World X/Y values (e.g. Alexis: 10.5, 5.2) appear to be LOCAL offsets in metres from their house position, NOT absolute World Space coordinates. BeenFore City houses are at World X=1050–1130, Y=880–900. The transform formula below converts Body Local → World Space for any entity.
A10: 🦴 A — BODY LOCAL SPACE (Layer 1) — Point 0 = Pelvis Centre
A11: Axis | B11: Direction | C11: Positive (+) | D11: Negative (−) | E11: Range | F11: Example: Frontal Bone | G11: Example: Femur (L) | H11: Example: Heart | I11: Unit | J11: Notes
A12: Z | B12: Back ↔ Front | C12: Forward / Anterior | D12: Backward / Posterior | E12: −0.1 to +0.15 m | F12: Z=+0.08 (anterior) | G12: Z=0 (neutral) | H12: Z=+0.02 (anterior) | I12: m | J12: Spine runs along −Z (posterior). Chest/face are +Z (anterior)
A13: 📍 POINT 0 — PELVIS CENTRE REFERENCE
A14: Parameter | B14: Value | C14: Unit | D14: Description | E14: Formula
A15: X₀ (Horizontal) | B15: 0 | C15: m | D15: Midline — no left/right offset | E15: Fixed = 0
A16: Y₀ (Vertical) | B16: 0 | C16: m | D16: Pelvis centre height baseline | E16: Fixed = 0
A17: Z₀ (Depth) | B17: 0 | C17: m | D17: Mid-coronal plane | E17: Fixed = 0
A18: Body Height Factor | B18: 0.5 | C18: m/unit | D18: Scales Y coords to real height | E18: Real_Y = Local_Y × Height_m
A19: Body Width Factor | B19: 0.2 | C19: m/unit | D19: Scales X coords to real width | E19: Real_X = Local_X × Width_m
A20: Reference Point | B20: Pelvis Centre | C20: — | D20: Anatomical landmark — stable across growth stages | E20: Consistent across Infant/Child/Adult
A22: 🌍 B — WORLD SPACE (Layer 2) — Point 0 = Earth Core Centre
A23: Axis | B23: Direction | C23: Positive (+) | D23: Negative (−) | E23: Range | F23: BeenFore City Value | G23: Unit | H23: Notes
A24: Z | B24: Core ↕ Sky (Altitude) | C24: Sky / Up ↑ | D24: ↓ Core / Down | E24: −6,371 km (core) to +∞ | F24: 0 m (ground level) | G24: m | H24: Z=0 = sea level / ground surface. Buildings extend +Z
A25: 🌐 WORLD LAYER HIERARCHY (Z-axis cross-section)
A26: Layer | B26: Z Range | C26: Thickness | D26: State | E26: Physics Type | F26: Relevance to A7DO
A27: Earth Core | B27: Z = 0 to −1,220 km | C27: 1,220 km | D27: Solid | E27: Gravitational | F27: Gravity source (9.81 m/s²)
A28: Outer Core | B28: Z = −1,220 to −3,400 km | C28: 2,180 km | D28: Liquid Metal | E28: Electromagnetic | F28: Magnetic field — compass orientation
A29: Mantle | B29: Z = −3,400 to −6,350 km | C29: 2,950 km | D29: Solid/Flowing | E29: Thermal Convection | F29: Heat source — geothermal
A30: Crust | B30: Z = −6,350 to −6,371 km | C30: 5–70 km | D30: Solid Rigid | E30: Elastic Solid | F30: Ground surface — collision layer
A31: Ground Level | B31: Z = 0 m | C31: — | D31: Surface | E31: Collision Solid | F31: A7DO & NPC standing plane
A32: Troposphere | B32: Z = 0 to +12 km | C32: 12 km | D32: Gas | E32: Fluid Gas | F32: Breathing air, weather, temperature
A33: Stratosphere | B33: Z = +12 to +50 km | C33: 38 km | D33: Gas | E33: Ozone Layer | F33: UV protection
A34: Thermosphere+ | B34: Z = +80 km to +∞ | C34: Variable | D34: Ionized/Vacuum | E34: Near Vacuum | F34: Space — beyond simulation scope
A36: 🔄 C — COORDINATE TRANSFORM — Body Local Space → World Space
A37: To place any body part in World Space: World_XYZ = Entity_World_Position + (Body_Local_XYZ × Scale_Factor). Scale_Factor converts normalised body coords (±1.0) to real metres based on entity height/width.
A38: Transform | B38: Formula | C38: Variables | D38: Example: A7DO Frontal Bone in World | E38: Example: NPC-001 Frontal Bone in World | F38: Notes
A39: World X | B39: W_X = Entity_X + (Local_X × Body_Width_m) | C39: Entity_X = NPC/A7DO world position X Local_X = body part local X Body_Width_m = body width in metres | D39: A7DO at H8 (X≈1090m) Frontal Bone Local_X=0 W_X = 1090 + (0 × 0.4) = 1090.0 m | E39: Alexis at H1 (X≈1050m) Frontal Bone Local_X=0 W_X = 1050 + (0 × 0.4) = 1050.0 m | F39: Body_Width_m ≈ 0.4m for adult (shoulder width)
A40: World Y | B40: W_Y = Entity_Y + (Local_Y × Body_Height_m) | C40: Entity_Y = NPC/A7DO world position Y Local_Y = body part local Y Body_Height_m = entity height in metres | D40: A7DO at H8 (Y≈880m) Frontal Bone Local_Y=0.85 Body_Height=0.5m (toddler) W_Y = 880 + (0.85 × 0.5) = 880.43 m | E40: Alexis at H1 (Y≈900m) Frontal Bone Local_Y=0.85 Body_Height=1.75m (adult) W_Y = 900 + (0.85 × 1.75) = 901.49 m | F40: Body_Height_m varies by age stage — see scale table below
A41: World Z | B41: W_Z = Ground_Z + (Local_Y × Body_Height_m) | C41: Ground_Z = altitude of standing surface Local_Y drives vertical height (Z in world = Y in body) | D41: A7DO standing on ground (Z=0) Frontal Bone Local_Y=0.85 W_Z = 0 + (0.85 × 0.5) = 0.43 m above ground | E41: Alexis standing (Z=0) Frontal Bone Local_Y=0.85 W_Z = 0 + (0.85 × 1.75) = 1.49 m above ground | F41: Body Y-axis maps to World Z-axis (vertical height above ground)
A42: Pelvis (Point 0) | B42: W_pelvis = Entity_World_Position | C42: The entity's world position IS the pelvis centre (Point 0 = pelvis in body space) | D42: A7DO pelvis = H8 world pos ≈ (1090, 880, 0) | E42: Alexis pelvis = H1 world pos ≈ (1050, 900, 0) | F42: All body parts computed relative to this anchor
A44: 📏 D — BODY SCALE FACTORS BY AGE STAGE
A45: Age Stage | B45: Age Range | C45: Height (m) | D45: Width (m) | E45: Body_Height_m | F45: Body_Width_m | G45: Pelvis Y offset (m) | H45: Head Y in World (m) | I45: Feet Y in World (m) | J45: Scale Source
...

Sheet 🫀 Body Systems
A1: ⚡ LIVE TICK PANEL — All values auto-update from 🧬 DNA Loop Engine B4 (Current Tick)
A2: Current Tick: | B2: ='🧬 DNA Loop Engine'!B4 -> 10000 | C2: Current Week: | D2: ='🧬 DNA Loop Engine'!B5 -> 125 | E2: Birth Status: | F2: ='🧬 DNA Loop Engine'!B8 -> 🎉 BIRTH COMPLETE
A3: Life Stage: | B3: ='🧬 DNA Loop Engine'!B15 -> 🧒 Toddler | C3: Age: | D3: ='🧬 DNA Loop Engine'!B16 -> 19.6 months (1.63 yrs) | E3: DNA Phase: | F3: ='🧬 DNA Loop Engine'!B11 -> Toddler
A4: Growth Factor: | B4: ='🧬 DNA Loop Engine'!B18 -> 1 | C4: Neural Gain: | D4: ='🧬 DNA Loop Engine'!B19 -> 1 | E4: Cord Status: | F4: ='🧬 DNA Loop Engine'!B22 -> 🔌 SEVERED
A5: G_phys (height): | B5: ='🧬 DNA Loop Engine'!B28 -> 1.706 | C5: Heart Rate: | D5: ='🧬 DNA Loop Engine'!B27 -> 70 | E5: Reflex Gain: | F5: ='🧬 DNA Loop Engine'!B20 -> 1
A6: 🫀 BODY SYSTEMS — Circulatory · Respiratory · Digestive · Sensory
A8: ❤️ CIRCULATORY SYSTEM
A9: Name | B9: Controlled Structure | C9: Neural Region | D9: Control Type | E9: Signal Pathway | F9: Feedback Source | G9: Activation Week | H9: Full Maturity Week | I9: Domain | J9: Current Week | K9: Growth Status | L9: Maturity % | M9: Local X | N9: Local Y | O9: Local Z | P9: Connection To | Q9: Flow Direction | R9: Flow Rate Factor
A10: Heart | B10: Organ | C10: Autonomic System | D10: Homeostatic | E10: Vagal Pathway | F10: Baroreceptors | G10: 8 | H10: 28 | I10: Embodiment | J10: ='🧬 DNA Loop Engine'!B5 -> 125 | K10: ✅ Mature | L10: 1 | M10: 0 | N10: 0.35 | O10: 0.05 | P10: Sternum | Q10: Central Pump | R10: 1
A11: Aorta | B11: Vessel | C11: Autonomic System | D11: Pressure Regulation | E11: Sympathetic Pathway | F11: Stretch Receptors | G11: 8 | H11: 28 | I11: Embodiment | J11: ='🧬 DNA Loop Engine'!B5 -> 125 | K11: ✅ Mature | L11: 1 | M11: 0 | N11: 0.4 | O11: 0.03 | P11: Heart | Q11: Ascending | R11: 0.95
A12: Pulmonary Artery | B12: Vessel | C12: Autonomic System | D12: Oxygen Exchange | E12: Vagal Pathway | F12: Chemoreceptors | G12: 8 | H12: 28 | I12: Embodiment | J12: ='🧬 DNA Loop Engine'!B5 -> 125 | K12: ✅ Mature | L12: 1 | M12: 0 | N12: 0.38 | O12: -0.02 | P12: Heart | Q12: To Lungs | R12: 0.9
A13: Pulmonary Veins | B13: Vessel | C13: Autonomic System | D13: Oxygen Return | E13: Vagal Pathway | F13: Chemoreceptors | G13: 8 | H13: 28 | I13: Embodiment | J13: ='🧬 DNA Loop Engine'!B5 -> 125 | K13: ✅ Mature | L13: 1 | M13: 0 | N13: 0.36 | O13: -0.02 | P13: Lungs | Q13: From Lungs | R13: 0.9
A14: Vena Cava | B14: Vessel | C14: Autonomic System | D14: Venous Return | E14: Sympathetic Pathway | F14: Pressure Sensors | G14: 8 | H14: 28 | I14: Embodiment | J14: ='🧬 DNA Loop Engine'!B5 -> 125 | K14: ✅ Mature | L14: 1 | M14: 0 | N14: 0.3 | O14: 0 | P14: Heart | Q14: To Heart | R14: 0.85
A15: Coronary Arteries | B15: Vessel | C15: Autonomic System | D15: Cardiac Perfusion | E15: Sympathetic Pathway | F15: Baroreceptors | G15: 8 | H15: 28 | I15: Embodiment | J15: ='🧬 DNA Loop Engine'!B5 -> 125 | K15: ✅ Mature | L15: 1 | M15: 0.02 | N15: 0.36 | O15: 0.04 | P15: Aorta | Q15: Cardiac Supply | R15: 0.8
A16: Capillary Networks | B16: Vessel | C16: Autonomic System | D16: Microcirculation | E16: Local Autoregulation | F16: Oxygen Sensors | G16: 12 | H16: 28 | I16: Embodiment | J16: ='🧬 DNA Loop Engine'!B5 -> 125 | K16: ✅ Mature | L16: 1 | M16: 0 | N16: 0 | O16: 0 | P16: Arterioles | Q16: Bidirectional | R16: 0.7
A17: Blood | B17: Fluid | C17: Autonomic System | D17: Transport Medium | E17: Endocrine Feedback | F17: Hemoglobin Sensors | G17: 12 | H17: 28 | I17: Embodiment | J17: ='🧬 DNA Loop Engine'!B5 -> 125 | K17: ✅ Mature | L17: 1 | M17: 0 | N17: 0 | O17: 0 | P17: All Vessels | Q17: Circulating | R17: 1
A18: Superior Vena Cava | B18: Vessel | C18: Autonomic System | D18: Upper Body Return | E18: Sympathetic Pathway | F18: Pressure Sensors | G18: 8 | H18: 28 | I18: Embodiment | J18: ='🧬 DNA Loop Engine'!B5 -> 125 | K18: ✅ Mature | L18: 1 | M18: 0 | N18: 0.45 | O18: 0 | P18: Heart | Q18: Upper Return | R18: 0.85
A19: Inferior Vena Cava | B19: Vessel | C19: Autonomic System | D19: Lower Body Return | E19: Sympathetic Pathway | F19: Pressure Sensors | G19: 8 | H19: 28 | I19: Embodiment | J19: ='🧬 DNA Loop Engine'!B5 -> 125 | K19: ✅ Mature | L19: 1 | M19: 0 | N19: 0.2 | O19: 0 | P19: Heart | Q19: Lower Return | R19: 0.85
A20: Carotid Arteries | B20: Vessel | C20: Autonomic System | D20: Cerebral Perfusion | E20: Sympathetic Pathway | F20: Baroreceptors | G20: 8 | H20: 28 | I20: Embodiment | J20: 125 | K20: ✅ Mature | L20: 1 | M20: 0.05 | N20: 0.6 | O20: 0.02 | P20: Aorta | Q20: To Brain | R20: 0.9
A21: Jugular Veins | B21: Vessel | C21: Autonomic System | D21: Cerebral Drainage | E21: Sympathetic Pathway | F21: Pressure Sensors | G21: 8 | H21: 28 | I21: Embodiment | J21: 125 | K21: ✅ Mature | L21: 1 | M21: 0.06 | N21: 0.55 | O21: 0 | P21: Brain | Q21: From Brain | R21: 0.85
A22: Hepatic Portal Vein | B22: Vessel | C22: Autonomic System | D22: Nutrient Transport | E22: Vagal Pathway | F22: Chemoreceptors | G22: 10 | H22: 28 | I22: Embodiment | J22: 125 | K22: ✅ Mature | L22: 1 | M22: 0.08 | N22: 0.25 | O22: 0.05 | P22: Intestines | Q22: Nutrient Carry | R22: 0.8
A23: Renal Arteries | B23: Vessel | C23: Autonomic System | D23: Kidney Perfusion | E23: Sympathetic Pathway | F23: Pressure Sensors | G23: 10 | H23: 28 | I23: Embodiment | J23: 125 | K23: ✅ Mature | L23: 1 | M23: 0.1 | N23: 0.15 | O23: 0 | P23: Aorta | Q23: To Kidneys | R23: 0.85
A24: Umbilical Arteries | B24: Vessel | C24: Autonomic System | D24: Waste Transport | E24: Vagal Pathway | F24: Chemoreceptors | G24: 4 | H24: 40 | I24: Embodiment | J24: 125 | K24: ✅ Mature | L24: 1 | M24: 0 | N24: -0.1 | O24: 0 | P24: Placenta | Q24: Waste Out | R24: 0.95
A25: Umbilical Vein | B25: Vessel | C25: Autonomic System | D25: Nutrient Delivery | E25: Vagal Pathway | F25: Oxygen Sensors | G25: 4 | H25: 40 | I25: Embodiment | J25: 125 | K25: ✅ Mature | L25: 1 | M25: 0 | N25: -0.1 | O25: 0.02 | P25: Placenta | Q25: Nutrients In | R25: 0.95
A26: Ductus Arteriosus | B26: Fetal Shunt | C26: Autonomic System | D26: Pulmonary Bypass | E26: Local Autoregulation | F26: Oxygen Sensors | G26: 6 | H26: 40 | I26: Embodiment | J26: 125 | K26: ✅ Mature | L26: 1 | M26: 0 | N26: 0.38 | O26: 0 | P26: Pulmonary/Aorta | Q26: Bypass | R26: 0.9
A27: Foramen Ovale | B27: Fetal Shunt | C27: Autonomic System | D27: Atrial Shunt | E27: Local Autoregulation | F27: Pressure Sensors | G27: 6 | H27: 40 | I27: Embodiment | J27: 125 | K27: ✅ Mature | L27: 1 | M27: 0 | N27: 0.35 | O27: 0.02 | P27: Atria | Q27: Atrial Bypass | R27: 0.9
A28: 🩸 CIRCULATORY SYSTEM SUMMARY
A29: Parameter | B29: Value | C29: Unit | E29: 🔗 CROSS-SYSTEM LINKS
A30: Total Components: | B30: 18 | E30: Linked Sheet | F30: Connection
A31: Vessels: | B31: 14 | E31: DNA Loop Engine | F31: Current Week (B5)
A32: Organs: | B32: 1 | E32: Respiratory Control | F32: O₂ Exchange
A33: Fetal Shunts: | B33: 2 | E33: Anatomy Growth Engine | F33: Heart Coordinates
A34: Fluids: | B34: 1 | E34: Neural Control | F34: Autonomic Pathways
A35: ⏳ Pending: | B35: 0
A36: 🔄 Developing: | B36: 0
A37: ✅ Mature: | B37: 18
A38: Average Maturity: | B38: 1 | C38: %
A39: 🫀 CARDIAC METRICS (from DNA Loop Engine)
A40: Heart Rate: | B40: 80 | C40: BPM | E40: Status: | F40: ✅ MATURE
A41: Cardiac Output: | B41: 0.16 | C41: L/min
...

Sheet 🔬 Subsystems
A1: 🔬 A7DO SUBSYSTEMS — P1 Proprioception · P2 Object Permanence · P3 Episodic Memory · P4 Value System · P6 Motor Planning
A2: All subsystems specified and ready for implementation. Change 🧬 DNA Loop Engine B4 to see current developmental stage for each system.
A3: ⚡ LIVE TICK PANEL
A4: Current Tick | B4: ='🧬 DNA Loop Engine'!B4 -> 10000 | C4: Current Week | D4: ='🧬 DNA Loop Engine'!B5 -> 125 | E4: Life Stage | F4: ='🧬 DNA Loop Engine'!B15 -> 🧒 Toddler | G4: Growth Factor | H4: ='🧬 DNA Loop Engine'!B18 -> 1 | I4: Neural Gain | J4: ='🧬 DNA Loop Engine'!B19 -> 1 | K4: Birth Status | L4: ='🧬 DNA Loop Engine'!B8 -> 🎉 BIRTH COMPLETE
A5: 📋 SUBSYSTEM OVERVIEW — All 5 Critical Path Systems
A6: Priority | B6: System | C6: Category | D6: Core Equation | E6: Current Stage | F6: Requires | G6: Unlocks | H6: v2.0 Status | I6: Build Phase
A7: P1 | B7: Proprioception | C7: Embodiment | D7: P_b(t) = K_s·θ + K_v·θ̇ + K_f·F_m + ε | E7: ='🧬 DNA Loop Engine'!B15&" — Stage 3 (Coordinated)" -> 🧒 Toddler — Stage 3 (Coordinated) | F7: Anatomy, Body Systems | G7: Motor Planning, Vestibular, Balance | H7: 🔴 Implement | I7: Phase 1
A8: P2 | B8: Object Permanence | C8: Vision/Cognition | D8: C_i(t) = C₀·exp(−λ·(t−t_lastSeen)) | E8: ='🧬 DNA Loop Engine'!B15&" — Stage 3 (Trajectory Pred.)" -> 🧒 Toddler — Stage 3 (Trajectory Pred.) | F8: Sensory Integration, Memory | G8: Language nouns, Motor reach | H8: 🔴 Implement | I8: Phase 1
A9: P3 | B9: Episodic Memory | C9: Cognition | D9: E_i = (S_i, A_i, T_i, U_i); w_i = σ(U_i) | E9: ='🧬 DNA Loop Engine'!B15&" — Stage 3 (Full Episodes)" -> 🧒 Toddler — Stage 3 (Full Episodes) | F9: Object Permanence, Emotion | G9: Theory of Mind, Identity | H9: 🔴 Implement | I9: Phase 1
A10: P4 | B10: Value System | C10: Motivation | D10: V(a) = R(a) + γ·E[V(s')]; dC/dt = −C/τ + k·novelty | E10: ='🧬 DNA Loop Engine'!B15&" — Stage 2 (Goal-Directed)" -> 🧒 Toddler — Stage 2 (Goal-Directed) | F10: Emotion Module, Energy/ATP | G10: All goal-directed behaviour | H10: 🔴 Implement | I10: Phase 1
A11: P6 | B11: Motor Planning | C11: Motor | D11: min J = ∫[(x−x_g)ᵀQ(x−x_g)+uᵀRu]dt; θ=J⁺·Δx | E11: ='🧬 DNA Loop Engine'!B15&" — Stage 2 (Coordinated Reach)" -> 🧒 Toddler — Stage 2 (Coordinated Reach) | F11: Proprioception, Object Perm., Value | G11: Tool use, Navigation, Grasping | H11: 🟡 Partial | I11: Phase 1
A13: 🦴 P1 — PROPRIOCEPTION
A14: Stage | B14: Weeks | C14: Age | D14: Capability | E14: Key Param | F14: Accuracy/Decay | G14: Feedback | H14: Current?
A15: 0 — None | B15: 0–40 | C15: Prenatal | D15: No body awareness | E15: 0 | F15: None | G15: None
A16: 1 — Limb Flail | B16: 40–60 | C16: 0–3 months | D16: Random limb movement | E16: 0.1 | F16: ±30cm | G16: None
A17: 2 — Basic Map | B17: 60–100 | C17: 3–12 months | D17: Rough limb position awareness | E17: 0.3 | F17: ±10cm | G17: Slow
A18: 3 — Coord. ★ | B18: 100–160 | C18: 12–24 months | D18: Coordinated reaching active | E18: 0.6 | F18: ±3cm | G18: Active | H18: ="★ NOW (Wk "&'🧬 DNA Loop Engine'!B5&")" -> ★ NOW (Wk 125)
A19: 4 — Predictive | B19: 160–260 | C19: 24–48 months | D19: Predictive proprioception | E19: 0.85 | F19: ±1cm | G19: Fast
A20: 5 — Full Schema | B20: 260+ | C20: 48+ months | D20: Full body schema | E20: 1.0 | F20: ±0.3cm | G20: Optimal
A22: 👁️ P2 — OBJECT PERMANENCE
A23: Stage | B23: Weeks | C23: Age | D23: Capability | E23: Key Param | F23: Accuracy/Decay | G23: Feedback | H23: Current?
A24: 0 — None | B24: 0–40 | C24: Prenatal | D24: No permanence — world resets | E24: N/A | F24: None | G24: None
A25: 1 — Short Pers. | B25: 40–80 | C25: 0–10 months | D25: Brief persistence (1–2 sec) | E25: 0.5 | F25: None | G25: None
A26: 2 — Hidden Track | B26: 80–120 | C26: 10–15 months | D26: Tracks hidden objects 10 sec | E26: 0.1 | F26: Linear | G26: Basic
A27: 3 — Traj. Pred. ★ | B27: 120–200 | C27: 15–25 months | D27: Predicts hidden object trajectory | E27: 0.05 | F27: Kinematic | G27: Relational | H27: ="★ NOW (Wk "&'🧬 DNA Loop Engine'!B5&")" -> ★ NOW (Wk 125)
A28: 4 — Abstract | B28: 200–350 | C28: 25–67 months | D28: Abstract permanence | E28: 0.01 | F28: Full | G28: Full
A29: 5 — Social | B29: 350+ | C29: 67+ months | D29: Social permanence + ToM | E29: 0.001 | F29: Intentional | G29: Social
A31: 💾 P3 — EPISODIC MEMORY
A32: Stage | B32: Weeks | C32: Age | D32: Capability | E32: Key Param | F32: Accuracy/Decay | G32: Feedback | H32: Current?
A33: 0 — None | B33: 0–40 | C33: Prenatal | D33: No episodic memory | E33: None | F33: None | G33: None
A34: 1 — Momentary | B34: 40–80 | C34: 0–10 months | D34: Momentary recall (seconds) | E34: <10s | F34: Basic | G34: None
A35: 2 — Short Seq. | B35: 80–120 | C35: 10–15 months | D35: Short sequences (minutes) | E35: <5min | F35: Moderate | G35: Partial
A36: 3 — Full Ep. ★ | B36: 120–200 | C36: 15–25 months | D36: Full episodes with context | E36: <1day | F36: Strong | G36: Forming | H36: ="★ NOW (Wk "&'🧬 DNA Loop Engine'!B5&")" -> ★ NOW (Wk 125)
A37: 4 — Narrative | B37: 200–350 | C37: 25–67 months | D37: Narrative memory chains | E37: <1wk | F37: Full | G37: Growing
